Line 55 update_todo: UtilityOperations.py
Error :
Traceback (most recent call last):
  File "c:\Users\16478\Desktop\PythonTraining\MyPython\MngoDB Practice\UtilityOperations.py", line 127, in <module>
    main()
  File "c:\Users\16478\Desktop\PythonTraining\MyPython\MngoDB Practice\UtilityOperations.py", line 116, in main
    update_todo(id = id )
TypeError: update_todo() got an unexpected keyword argument 'id'
PS C:\Users\16478\Desktop\PythonTraining\MyPython\MngoDB Practice>